{"record": {"timestamp": 1686187799775, "time": "2023-06-08 09:29:59", "exception": null, "message": "Traceback (most recent call last):\n  File \"/Users/zhouzhiyong/opt/anaconda3/envs/EasyAirflow/lib/python3.10/site-packages/sqlalchemy/engine/base.py\", line 3361, in _wrap_pool_connect\n    return fn()\n  File \"/Users/zhouzhiyong/opt/anaconda3/envs/EasyAirflow/lib/python3.10/site-packages/sqlalchemy/pool/base.py\", line 327, in connect\n    return _ConnectionFairy._checkout(self)\n  File \"/Users/zhouzhiyong/opt/anaconda3/envs/EasyAirflow/lib/python3.10/site-packages/sqlalchemy/pool/base.py\", line 894, in _checkout\n    fairy = _ConnectionRecord.checkout(pool)\n  File \"/Users/zhouzhiyong/opt/anaconda3/envs/EasyAirflow/lib/python3.10/site-packages/sqlalchemy/pool/base.py\", line 493, in checkout\n    rec = pool._do_get()\n  File \"/Users/zhouzhiyong/opt/anaconda3/envs/EasyAirflow/lib/python3.10/site-packages/sqlalchemy/pool/impl.py\", line 145, in _do_get\n    with util.safe_reraise():\n  File \"/Users/zhouzhiyong/opt/anaconda3/envs/EasyAirflow/lib/python3.10/site-packages/sqlalchemy/util/langhelpers.py\", line 70, in __exit__\n    compat.raise_(\n  File \"/Users/zhouzhiyong/opt/anaconda3/envs/EasyAirflow/lib/python3.10/site-packages/sqlalchemy/util/compat.py\", line 211, in raise_\n    raise exception\n  File \"/Users/zhouzhiyong/opt/anaconda3/envs/EasyAirflow/lib/python3.10/site-packages/sqlalchemy/pool/impl.py\", line 143, in _do_get\n    return self._create_connection()\n  File \"/Users/zhouzhiyong/opt/anaconda3/envs/EasyAirflow/lib/python3.10/site-packages/sqlalchemy/pool/base.py\", line 273, in _create_connection\n    return _ConnectionRecord(self)\n  File \"/Users/zhouzhiyong/opt/anaconda3/envs/EasyAirflow/lib/python3.10/site-packages/sqlalchemy/pool/base.py\", line 388, in __init__\n    self.__connect()\n  File \"/Users/zhouzhiyong/opt/anaconda3/envs/EasyAirflow/lib/python3.10/site-packages/sqlalchemy/pool/base.py\", line 690, in __connect\n    with util.safe_reraise():\n  File \"/Users/zhouzhiyong/opt/anaconda3/envs/EasyAirflow/lib/python3.10/site-packages/sqlalchemy/util/langhelpers.py\", line 70, in __exit__\n    compat.raise_(\n  File \"/Users/zhouzhiyong/opt/anaconda3/envs/EasyAirflow/lib/python3.10/site-packages/sqlalchemy/util/compat.py\", line 211, in raise_\n    raise exception\n  File \"/Users/zhouzhiyong/opt/anaconda3/envs/EasyAirflow/lib/python3.10/site-packages/sqlalchemy/pool/base.py\", line 686, in __connect\n    self.dbapi_connection = connection = pool._invoke_creator(self)\n  File \"/Users/zhouzhiyong/opt/anaconda3/envs/EasyAirflow/lib/python3.10/site-packages/sqlalchemy/engine/create.py\", line 574, in connect\n    return dialect.connect(*cargs, **cparams)\n  File \"/Users/zhouzhiyong/opt/anaconda3/envs/EasyAirflow/lib/python3.10/site-packages/sqlalchemy/engine/default.py\", line 598, in connect\n    return self.dbapi.connect(*cargs, **cparams)\n  File \"/Users/zhouzhiyong/opt/anaconda3/envs/EasyAirflow/lib/python3.10/site-packages/MySQLdb/__init__.py\", line 130, in Connect\n    return Connection(*args, **kwargs)\n  File \"/Users/zhouzhiyong/opt/anaconda3/envs/EasyAirflow/lib/python3.10/site-packages/MySQLdb/connections.py\", line 185, in __init__\n    super().__init__(*args, **kwargs2)\nMySQLdb._exceptions.OperationalError: (2002, \"Can't connect to local MySQL server through socket '/tmp/mysql.sock' (2)\")\n\nThe above exception was the direct cause of the following exception:\n\nTraceback (most recent call last):\n  File \"/Users/zhouzhiyong/Desktop/EasyAirflow/rest_api/utils/response_safe.py\", line 40, in wraps\n    resp = f(*args, **kwargs)\n  File \"/Users/zhouzhiyong/Desktop/EasyAirflow/rest_api/endpoints/resources/task_instance_list_resource.py\", line 80, in post\n    timestamp_list = TaskDefine.get_backfill_task_plan_execution_date_timepstamp(\n  File \"/Users/zhouzhiyong/Desktop/EasyAirflow/rest_api/utils/database.py\", line 109, in wrapper\n    return func(*args, **kwargs)\n  File \"/Users/zhouzhiyong/Desktop/EasyAirflow/rest_api/endpoints/models/task_model.py\", line 316, in get_backfill_task_plan_execution_date_timepstamp\n    airflow_task = TaskDefine.get_task(task_id)\n  File \"/Users/zhouzhiyong/Desktop/EasyAirflow/rest_api/utils/database.py\", line 109, in wrapper\n    return func(*args, **kwargs)\n  File \"/Users/zhouzhiyong/Desktop/EasyAirflow/rest_api/endpoints/models/task_model.py\", line 171, in get_task\n    task = qry.first()\n  File \"/Users/zhouzhiyong/opt/anaconda3/envs/EasyAirflow/lib/python3.10/site-packages/sqlalchemy/orm/query.py\", line 2824, in first\n    return self.limit(1)._iter().first()\n  File \"/Users/zhouzhiyong/opt/anaconda3/envs/EasyAirflow/lib/python3.10/site-packages/sqlalchemy/orm/query.py\", line 2916, in _iter\n    result = self.session.execute(\n  File \"/Users/zhouzhiyong/opt/anaconda3/envs/EasyAirflow/lib/python3.10/site-packages/sqlalchemy/orm/session.py\", line 1713, in execute\n    conn = self._connection_for_bind(bind)\n  File \"/Users/zhouzhiyong/opt/anaconda3/envs/EasyAirflow/lib/python3.10/site-packages/sqlalchemy/orm/session.py\", line 1552, in _connection_for_bind\n    return self._transaction._connection_for_bind(\n  File \"/Users/zhouzhiyong/opt/anaconda3/envs/EasyAirflow/lib/python3.10/site-packages/sqlalchemy/orm/session.py\", line 747, in _connection_for_bind\n    conn = bind.connect()\n  File \"/Users/zhouzhiyong/opt/anaconda3/envs/EasyAirflow/lib/python3.10/site-packages/sqlalchemy/engine/base.py\", line 3315, in connect\n    return self._connection_cls(self, close_with_result=close_with_result)\n  File \"/Users/zhouzhiyong/opt/anaconda3/envs/EasyAirflow/lib/python3.10/site-packages/sqlalchemy/engine/base.py\", line 96, in __init__\n    else engine.raw_connection()\n  File \"/Users/zhouzhiyong/opt/anaconda3/envs/EasyAirflow/lib/python3.10/site-packages/sqlalchemy/engine/base.py\", line 3394, in raw_connection\n    return self._wrap_pool_connect(self.pool.connect, _connection)\n  File \"/Users/zhouzhiyong/opt/anaconda3/envs/EasyAirflow/lib/python3.10/site-packages/sqlalchemy/engine/base.py\", line 3364, in _wrap_pool_connect\n    Connection._handle_dbapi_exception_noconnection(\n  File \"/Users/zhouzhiyong/opt/anaconda3/envs/EasyAirflow/lib/python3.10/site-packages/sqlalchemy/engine/base.py\", line 2198, in _handle_dbapi_exception_noconnection\n    util.raise_(\n  File \"/Users/zhouzhiyong/opt/anaconda3/envs/EasyAirflow/lib/python3.10/site-packages/sqlalchemy/util/compat.py\", line 211, in raise_\n    raise exception\n  File \"/Users/zhouzhiyong/opt/anaconda3/envs/EasyAirflow/lib/python3.10/site-packages/sqlalchemy/engine/base.py\", line 3361, in _wrap_pool_connect\n    return fn()\n  File \"/Users/zhouzhiyong/opt/anaconda3/envs/EasyAirflow/lib/python3.10/site-packages/sqlalchemy/pool/base.py\", line 327, in connect\n    return _ConnectionFairy._checkout(self)\n  File \"/Users/zhouzhiyong/opt/anaconda3/envs/EasyAirflow/lib/python3.10/site-packages/sqlalchemy/pool/base.py\", line 894, in _checkout\n    fairy = _ConnectionRecord.checkout(pool)\n  File \"/Users/zhouzhiyong/opt/anaconda3/envs/EasyAirflow/lib/python3.10/site-packages/sqlalchemy/pool/base.py\", line 493, in checkout\n    rec = pool._do_get()\n  File \"/Users/zhouzhiyong/opt/anaconda3/envs/EasyAirflow/lib/python3.10/site-packages/sqlalchemy/pool/impl.py\", line 145, in _do_get\n    with util.safe_reraise():\n  File \"/Users/zhouzhiyong/opt/anaconda3/envs/EasyAirflow/lib/python3.10/site-packages/sqlalchemy/util/langhelpers.py\", line 70, in __exit__\n    compat.raise_(\n  File \"/Users/zhouzhiyong/opt/anaconda3/envs/EasyAirflow/lib/python3.10/site-packages/sqlalchemy/util/compat.py\", line 211, in raise_\n    raise exception\n  File \"/Users/zhouzhiyong/opt/anaconda3/envs/EasyAirflow/lib/python3.10/site-packages/sqlalchemy/pool/impl.py\", line 143, in _do_get\n    return self._create_connection()\n  File \"/Users/zhouzhiyong/opt/anaconda3/envs/EasyAirflow/lib/python3.10/site-packages/sqlalchemy/pool/base.py\", line 273, in _create_connection\n    return _ConnectionRecord(self)\n  File \"/Users/zhouzhiyong/opt/anaconda3/envs/EasyAirflow/lib/python3.10/site-packages/sqlalchemy/pool/base.py\", line 388, in __init__\n    self.__connect()\n  File \"/Users/zhouzhiyong/opt/anaconda3/envs/EasyAirflow/lib/python3.10/site-packages/sqlalchemy/pool/base.py\", line 690, in __connect\n    with util.safe_reraise():\n  File \"/Users/zhouzhiyong/opt/anaconda3/envs/EasyAirflow/lib/python3.10/site-packages/sqlalchemy/util/langhelpers.py\", line 70, in __exit__\n    compat.raise_(\n  File \"/Users/zhouzhiyong/opt/anaconda3/envs/EasyAirflow/lib/python3.10/site-packages/sqlalchemy/util/compat.py\", line 211, in raise_\n    raise exception\n  File \"/Users/zhouzhiyong/opt/anaconda3/envs/EasyAirflow/lib/python3.10/site-packages/sqlalchemy/pool/base.py\", line 686, in __connect\n    self.dbapi_connection = connection = pool._invoke_creator(self)\n  File \"/Users/zhouzhiyong/opt/anaconda3/envs/EasyAirflow/lib/python3.10/site-packages/sqlalchemy/engine/create.py\", line 574, in connect\n    return dialect.connect(*cargs, **cparams)\n  File \"/Users/zhouzhiyong/opt/anaconda3/envs/EasyAirflow/lib/python3.10/site-packages/sqlalchemy/engine/default.py\", line 598, in connect\n    return self.dbapi.connect(*cargs, **cparams)\n  File \"/Users/zhouzhiyong/opt/anaconda3/envs/EasyAirflow/lib/python3.10/site-packages/MySQLdb/__init__.py\", line 130, in Connect\n    return Connection(*args, **kwargs)\n  File \"/Users/zhouzhiyong/opt/anaconda3/envs/EasyAirflow/lib/python3.10/site-packages/MySQLdb/connections.py\", line 185, in __init__\n    super().__init__(*args, **kwargs2)\nsqlalchemy.exc.OperationalError: (MySQLdb._exceptions.OperationalError) (2002, \"Can't connect to local MySQL server through socket '/tmp/mysql.sock' (2)\")\n(Background on this error at: https://sqlalche.me/e/14/e3q8)\n", "file": "response_safe.py", "line": 45, "function": "wraps", "level": "ERROR", "name": "utils.response_safe", "process": 21048, "thread": 13069443072, "extra": {}}, "trace": {"service": "airflow-plus", "hostname": "zhouzhiyongdeMac-mini.local", "span_name": null, "span_id": "0000000000000000", "trace_id": "275eed5ca908999cbe45fb910ec1b2ae", "parent_span_id": null}}
{"record": {"timestamp": 1686188012235, "time": "2023-06-08 09:33:32", "exception": null, "message": "Traceback (most recent call last):\n  File \"/Users/zhouzhiyong/Desktop/EasyAirflow/rest_api/utils/response_safe.py\", line 40, in wraps\n    resp = f(*args, **kwargs)\n  File \"/Users/zhouzhiyong/Desktop/EasyAirflow/rest_api/endpoints/resources/task_instance_list_resource.py\", line 85, in post\n    TaskHandlers.complement_task_instances(task_id, timestamp_list)\n  File \"/Users/zhouzhiyong/Desktop/EasyAirflow/rest_api/endpoints/handlers/airflow_task_handlers.py\", line 249, in complement_task_instances\n    cls.back_fill(dag_id, task_id, execution_date)\n  File \"/Users/zhouzhiyong/Desktop/EasyAirflow/rest_api/endpoints/handlers/airflow_task_handlers.py\", line 199, in back_fill\n    dag = cls.get_dag(dag_id)\n  File \"/Users/zhouzhiyong/Desktop/EasyAirflow/rest_api/endpoints/handlers/airflow_task_handlers.py\", line 182, in get_dag\n    store_serialized_dags=read_store_serialized_dags()\n  File \"/Users/zhouzhiyong/Desktop/EasyAirflow/rest_api/endpoints/handlers/airflow_task_handlers.py\", line 178, in read_store_serialized_dags\n    return conf.getboolean('core', 'store_serialized_dags')\n  File \"/Users/zhouzhiyong/opt/anaconda3/envs/EasyAirflow/lib/python3.10/site-packages/airflow/configuration.py\", line 765, in getboolean\n    val = str(self.get(section, key, _extra_stacklevel=1, **kwargs)).lower().strip()\n  File \"/Users/zhouzhiyong/opt/anaconda3/envs/EasyAirflow/lib/python3.10/site-packages/airflow/configuration.py\", line 677, in get\n    raise AirflowConfigException(f\"section/key [{section}/{key}] not found in config\")\nairflow.exceptions.AirflowConfigException: section/key [core/store_serialized_dags] not found in config\n", "file": "response_safe.py", "line": 45, "function": "wraps", "level": "ERROR", "name": "utils.response_safe", "process": 21131, "thread": 13147938816, "extra": {}}, "trace": {"service": "airflow-plus", "hostname": "zhouzhiyongdeMac-mini.local", "span_name": null, "span_id": "0000000000000000", "trace_id": "9d4b64e3414b19c8715c9ddebefd7350", "parent_span_id": null}}
{"record": {"timestamp": 1686188295392, "time": "2023-06-08 09:38:15", "exception": null, "message": "Traceback (most recent call last):\n  File \"/Users/zhouzhiyong/Desktop/EasyAirflow/rest_api/utils/response_safe.py\", line 40, in wraps\n    resp = f(*args, **kwargs)\n  File \"/Users/zhouzhiyong/Desktop/EasyAirflow/rest_api/endpoints/resources/task_instance_list_resource.py\", line 85, in post\n    TaskHandlers.complement_task_instances(task_id, timestamp_list)\n  File \"/Users/zhouzhiyong/Desktop/EasyAirflow/rest_api/endpoints/handlers/airflow_task_handlers.py\", line 249, in complement_task_instances\n    cls.back_fill(dag_id, task_id, execution_date)\n  File \"/Users/zhouzhiyong/Desktop/EasyAirflow/rest_api/endpoints/handlers/airflow_task_handlers.py\", line 199, in back_fill\n    dag = cls.get_dag(dag_id)\n  File \"/Users/zhouzhiyong/Desktop/EasyAirflow/rest_api/endpoints/handlers/airflow_task_handlers.py\", line 182, in get_dag\n    store_serialized_dags=read_store_serialized_dags()\n  File \"/Users/zhouzhiyong/Desktop/EasyAirflow/rest_api/endpoints/handlers/airflow_task_handlers.py\", line 178, in read_store_serialized_dags\n    return conf.getboolean('core', 'read_dags_from_db')\n  File \"/Users/zhouzhiyong/opt/anaconda3/envs/EasyAirflow/lib/python3.10/site-packages/airflow/configuration.py\", line 765, in getboolean\n    val = str(self.get(section, key, _extra_stacklevel=1, **kwargs)).lower().strip()\n  File \"/Users/zhouzhiyong/opt/anaconda3/envs/EasyAirflow/lib/python3.10/site-packages/airflow/configuration.py\", line 677, in get\n    raise AirflowConfigException(f\"section/key [{section}/{key}] not found in config\")\nairflow.exceptions.AirflowConfigException: section/key [core/read_dags_from_db] not found in config\n", "file": "response_safe.py", "line": 45, "function": "wraps", "level": "ERROR", "name": "utils.response_safe", "process": 21251, "thread": 13151559680, "extra": {}}, "trace": {"service": "airflow-plus", "hostname": "zhouzhiyongdeMac-mini.local", "span_name": null, "span_id": "0000000000000000", "trace_id": "c40798b783cd855d0a0b78208173c3ea", "parent_span_id": null}}
{"record": {"timestamp": 1686188641893, "time": "2023-06-08 09:44:01", "exception": null, "message": "Traceback (most recent call last):\n  File \"/Users/zhouzhiyong/Desktop/EasyAirflow/rest_api/utils/response_safe.py\", line 40, in wraps\n    resp = f(*args, **kwargs)\n  File \"/Users/zhouzhiyong/Desktop/EasyAirflow/rest_api/endpoints/resources/task_instance_list_resource.py\", line 85, in post\n    TaskHandlers.complement_task_instances(task_id, timestamp_list)\n  File \"/Users/zhouzhiyong/Desktop/EasyAirflow/rest_api/endpoints/handlers/airflow_task_handlers.py\", line 244, in complement_task_instances\n    cls.back_fill(dag_id, task_id, execution_date)\n  File \"/Users/zhouzhiyong/Desktop/EasyAirflow/rest_api/endpoints/handlers/airflow_task_handlers.py\", line 194, in back_fill\n    dag = cls.get_dag(dag_id)\n  File \"/Users/zhouzhiyong/Desktop/EasyAirflow/rest_api/endpoints/handlers/airflow_task_handlers.py\", line 181, in get_dag\n    raise DagNotFound(\"Dag id {} not found\".format(dag_id))\nairflow.exceptions.DagNotFound: Dag id _Landsat-dag-7069854774769745920 not found\n", "file": "response_safe.py", "line": 45, "function": "wraps", "level": "ERROR", "name": "utils.response_safe", "process": 21387, "thread": 13079797760, "extra": {}}, "trace": {"service": "airflow-plus", "hostname": "zhouzhiyongdeMac-mini.local", "span_name": null, "span_id": "0000000000000000", "trace_id": "5b5305c527851740bebc4af1f63e56b7", "parent_span_id": null}}
{"record": {"timestamp": 1686188812383, "time": "2023-06-08 09:46:52", "exception": null, "message": "Traceback (most recent call last):\n  File \"/Users/zhouzhiyong/Desktop/EasyAirflow/rest_api/utils/response_safe.py\", line 40, in wraps\n    resp = f(*args, **kwargs)\n  File \"/Users/zhouzhiyong/Desktop/EasyAirflow/rest_api/endpoints/resources/task_instance_list_resource.py\", line 85, in post\n    TaskHandlers.complement_task_instances(task_id, timestamp_list)\n  File \"/Users/zhouzhiyong/Desktop/EasyAirflow/rest_api/endpoints/handlers/airflow_task_handlers.py\", line 242, in complement_task_instances\n    cls.back_fill(dag_id, task_id, execution_date)\n  File \"/Users/zhouzhiyong/Desktop/EasyAirflow/rest_api/endpoints/handlers/airflow_task_handlers.py\", line 207, in back_fill\n    ti = EasyAirflowTaskInstance(task=task, execution_date=execution_date)\n  File \"<string>\", line 4, in __init__\n  File \"/Users/zhouzhiyong/opt/anaconda3/envs/EasyAirflow/lib/python3.10/site-packages/sqlalchemy/orm/state.py\", line 481, in _initialize_instance\n    with util.safe_reraise():\n  File \"/Users/zhouzhiyong/opt/anaconda3/envs/EasyAirflow/lib/python3.10/site-packages/sqlalchemy/util/langhelpers.py\", line 70, in __exit__\n    compat.raise_(\n  File \"/Users/zhouzhiyong/opt/anaconda3/envs/EasyAirflow/lib/python3.10/site-packages/sqlalchemy/util/compat.py\", line 211, in raise_\n    raise exception\n  File \"/Users/zhouzhiyong/opt/anaconda3/envs/EasyAirflow/lib/python3.10/site-packages/sqlalchemy/orm/state.py\", line 479, in _initialize_instance\n    return manager.original_init(*mixed[1:], **kwargs)\n  File \"<string>\", line 6, in __init__\n  File \"/Users/zhouzhiyong/opt/anaconda3/envs/EasyAirflow/lib/python3.10/site-packages/airflow/models/taskinstance.py\", line 528, in __init__\n    raise DagRunNotFound(\nairflow.exceptions.DagRunNotFound: DagRun for '_Landsat-dag-7069854774769745920' with date 2023-05-07T09:50:00+00:00 not found\n", "file": "response_safe.py", "line": 45, "function": "wraps", "level": "ERROR", "name": "utils.response_safe", "process": 21453, "thread": 13133193216, "extra": {}}, "trace": {"service": "airflow-plus", "hostname": "zhouzhiyongdeMac-mini.local", "span_name": null, "span_id": "0000000000000000", "trace_id": "7756affb6a13a7fd4d9c51d3f3b91d50", "parent_span_id": null}}
{"record": {"timestamp": 1686207000977, "time": "2023-06-08 14:50:00", "exception": null, "message": "Traceback (most recent call last):\n  File \"/Users/zhouzhiyong/Desktop/EasyAirflow/rest_api/utils/response_safe.py\", line 40, in wraps\n    resp = f(*args, **kwargs)\n  File \"/Users/zhouzhiyong/Desktop/EasyAirflow/rest_api/endpoints/resources/task_instance_list_resource.py\", line 85, in post\n    TaskHandlers.complement_task_instances(task_id, timestamp_list)\n  File \"/Users/zhouzhiyong/Desktop/EasyAirflow/rest_api/endpoints/handlers/airflow_task_handlers.py\", line 246, in complement_task_instances\n    cls.back_fill(dag_id, task_id, execution_date)\n  File \"/Users/zhouzhiyong/Desktop/EasyAirflow/rest_api/endpoints/handlers/airflow_task_handlers.py\", line 211, in back_fill\n    ti.run()\n  File \"/Users/zhouzhiyong/opt/anaconda3/envs/EasyAirflow/lib/python3.10/site-packages/airflow/utils/session.py\", line 76, in wrapper\n    return func(*args, session=session, **kwargs)\n  File \"/Users/zhouzhiyong/opt/anaconda3/envs/EasyAirflow/lib/python3.10/site-packages/airflow/models/taskinstance.py\", line 1728, in run\n    res = self.check_and_change_state_before_execution(\n  File \"/Users/zhouzhiyong/opt/anaconda3/envs/EasyAirflow/lib/python3.10/site-packages/airflow/utils/session.py\", line 73, in wrapper\n    return func(*args, **kwargs)\n  File \"/Users/zhouzhiyong/opt/anaconda3/envs/EasyAirflow/lib/python3.10/site-packages/airflow/models/taskinstance.py\", line 1284, in check_and_change_state_before_execution\n    if not self.are_dependencies_met(\n  File \"/Users/zhouzhiyong/opt/anaconda3/envs/EasyAirflow/lib/python3.10/site-packages/airflow/utils/session.py\", line 73, in wrapper\n    return func(*args, **kwargs)\n  File \"/Users/zhouzhiyong/opt/anaconda3/envs/EasyAirflow/lib/python3.10/site-packages/airflow/models/taskinstance.py\", line 1112, in are_dependencies_met\n    for dep_status in self.get_failed_dep_statuses(dep_context=dep_context, session=session):\n  File \"/Users/zhouzhiyong/opt/anaconda3/envs/EasyAirflow/lib/python3.10/site-packages/airflow/models/taskinstance.py\", line 1133, in get_failed_dep_statuses\n    for dep_status in dep.get_dep_statuses(self, session, dep_context):\n  File \"/Users/zhouzhiyong/opt/anaconda3/envs/EasyAirflow/lib/python3.10/site-packages/airflow/ti_deps/deps/base_ti_dep.py\", line 111, in get_dep_statuses\n    yield from self._get_dep_statuses(ti, session, cxt)\n  File \"/Users/zhouzhiyong/opt/anaconda3/envs/EasyAirflow/lib/python3.10/site-packages/airflow/ti_deps/deps/not_previously_skipped_dep.py\", line 47, in _get_dep_statuses\n    finished_tis = dep_context.ensure_finished_tis(ti.get_dagrun(session), session)\n  File \"/Users/zhouzhiyong/opt/anaconda3/envs/EasyAirflow/lib/python3.10/site-packages/airflow/utils/session.py\", line 73, in wrapper\n    return func(*args, **kwargs)\n  File \"/Users/zhouzhiyong/opt/anaconda3/envs/EasyAirflow/lib/python3.10/site-packages/airflow/models/taskinstance.py\", line 1214, in get_dagrun\n    dr = session.query(DagRun).filter(DagRun.dag_id == self.dag_id, DagRun.run_id == self.run_id).one()\n  File \"/Users/zhouzhiyong/opt/anaconda3/envs/EasyAirflow/lib/python3.10/site-packages/sqlalchemy/orm/query.py\", line 2870, in one\n    return self._iter().one()\n  File \"/Users/zhouzhiyong/opt/anaconda3/envs/EasyAirflow/lib/python3.10/site-packages/sqlalchemy/engine/result.py\", line 1522, in one\n    return self._only_one_row(\n  File \"/Users/zhouzhiyong/opt/anaconda3/envs/EasyAirflow/lib/python3.10/site-packages/sqlalchemy/engine/result.py\", line 562, in _only_one_row\n    raise exc.NoResultFound(\nsqlalchemy.exc.NoResultFound: No row was found when one was required\n", "file": "response_safe.py", "line": 45, "function": "wraps", "level": "ERROR", "name": "utils.response_safe", "process": 25860, "thread": 13070245888, "extra": {}}, "trace": {"service": "airflow-plus", "hostname": "zhouzhiyongdeMac-mini.local", "span_name": null, "span_id": "0000000000000000", "trace_id": "8908d4ed30c0c57055a2311ec28aa4d0", "parent_span_id": null}}
{"record": {"timestamp": 1686217502329, "time": "2023-06-08 17:45:02", "exception": null, "message": "Traceback (most recent call last):\n  File \"/Users/zhouzhiyong/Desktop/EasyAirflow/rest_api/utils/response_safe.py\", line 40, in wraps\n    resp = f(*args, **kwargs)\n  File \"/Users/zhouzhiyong/Desktop/EasyAirflow/rest_api/endpoints/resources/task_instance_list_resource.py\", line 82, in post\n    start_date, end_date = TaskDefine.get_backfill_start_end_time(start_plan_execution_date, end_plan_execution_date)\n  File \"/Users/zhouzhiyong/Desktop/EasyAirflow/rest_api/utils/database.py\", line 109, in wrapper\n    return func(*args, **kwargs)\nTypeError: TaskDefine.get_backfill_start_end_time() got an unexpected keyword argument 'session'\n", "file": "response_safe.py", "line": 45, "function": "wraps", "level": "ERROR", "name": "utils.response_safe", "process": 30236, "thread": 13090398208, "extra": {}}, "trace": {"service": "airflow-plus", "hostname": "zhouzhiyongdeMac-mini.local", "span_name": null, "span_id": "0000000000000000", "trace_id": "636c0926e7f2ad95b68ad0c9afa8e35e", "parent_span_id": null}}
{"record": {"timestamp": 1686217571748, "time": "2023-06-08 17:46:11", "exception": null, "message": "Traceback (most recent call last):\n  File \"/Users/zhouzhiyong/Desktop/EasyAirflow/rest_api/utils/response_safe.py\", line 40, in wraps\n    resp = f(*args, **kwargs)\n  File \"/Users/zhouzhiyong/Desktop/EasyAirflow/rest_api/endpoints/resources/task_instance_list_resource.py\", line 83, in post\n    TaskHandlers.back_fill(task_id, dag_id, start_date, end_date)\n  File \"/Users/zhouzhiyong/Desktop/EasyAirflow/rest_api/endpoints/handlers/airflow_task_handlers.py\", line 196, in back_fill\n    dag = cls.get_dag(dag_id)\n  File \"/Users/zhouzhiyong/Desktop/EasyAirflow/rest_api/endpoints/handlers/airflow_task_handlers.py\", line 178, in get_dag\n    raise DagNotFound(\"Dag id {} not found in DagModel\".format(dag_id))\nairflow.exceptions.DagNotFound: Dag id _Landsat-task-7069854799495168000 not found in DagModel\n", "file": "response_safe.py", "line": 45, "function": "wraps", "level": "ERROR", "name": "utils.response_safe", "process": 30277, "thread": 13073227776, "extra": {}}, "trace": {"service": "airflow-plus", "hostname": "zhouzhiyongdeMac-mini.local", "span_name": null, "span_id": "0000000000000000", "trace_id": "bedcb1c57ab5a358f0b7bc55b4af9af1", "parent_span_id": null}}
{"record": {"timestamp": 1686217710441, "time": "2023-06-08 17:48:30", "exception": null, "message": "Traceback (most recent call last):\n  File \"/Users/zhouzhiyong/Desktop/EasyAirflow/rest_api/utils/response_safe.py\", line 40, in wraps\n    resp = f(*args, **kwargs)\n  File \"/Users/zhouzhiyong/Desktop/EasyAirflow/rest_api/endpoints/resources/task_instance_list_resource.py\", line 85, in post\n    TaskHandlers.back_fill(task_id, dag_id, start_date, end_date)\n  File \"/Users/zhouzhiyong/Desktop/EasyAirflow/rest_api/endpoints/handlers/airflow_task_handlers.py\", line 196, in back_fill\n    dag = cls.get_dag(dag_id)\n  File \"/Users/zhouzhiyong/Desktop/EasyAirflow/rest_api/endpoints/handlers/airflow_task_handlers.py\", line 178, in get_dag\n    raise DagNotFound(\"Dag id {} not found in DagModel\".format(dag_id))\nairflow.exceptions.DagNotFound: Dag id _Landsat-task-7069854799495168000 not found in DagModel\n", "file": "response_safe.py", "line": 45, "function": "wraps", "level": "ERROR", "name": "utils.response_safe", "process": 30353, "thread": 13200171008, "extra": {}}, "trace": {"service": "airflow-plus", "hostname": "zhouzhiyongdeMac-mini.local", "span_name": null, "span_id": "0000000000000000", "trace_id": "018bdc0fdc8d8fa35dc08ff08e8d0e7e", "parent_span_id": null}}
{"record": {"timestamp": 1686217758601, "time": "2023-06-08 17:49:18", "exception": null, "message": "Traceback (most recent call last):\n  File \"/Users/zhouzhiyong/Desktop/EasyAirflow/rest_api/utils/response_safe.py\", line 40, in wraps\n    resp = f(*args, **kwargs)\n  File \"/Users/zhouzhiyong/Desktop/EasyAirflow/rest_api/endpoints/resources/task_instance_list_resource.py\", line 85, in post\n    TaskHandlers.back_fill(task_id, dag_id, start_date, end_date)\n  File \"/Users/zhouzhiyong/Desktop/EasyAirflow/rest_api/endpoints/handlers/airflow_task_handlers.py\", line 196, in back_fill\n    dag = cls.get_dag(dag_id)\n  File \"/Users/zhouzhiyong/Desktop/EasyAirflow/rest_api/endpoints/handlers/airflow_task_handlers.py\", line 178, in get_dag\n    raise DagNotFound(\"Dag id {} not found in DagModel\".format(dag_id))\nairflow.exceptions.DagNotFound: Dag id _Landsat-task-7069854799495168000 not found in DagModel\n", "file": "response_safe.py", "line": 45, "function": "wraps", "level": "ERROR", "name": "utils.response_safe", "process": 30353, "thread": 13200171008, "extra": {}}, "trace": {"service": "airflow-plus", "hostname": "zhouzhiyongdeMac-mini.local", "span_name": null, "span_id": "0000000000000000", "trace_id": "018bdc0fdc8d8fa35dc08ff08e8d0e7e", "parent_span_id": null}}
{"record": {"timestamp": 1686217785797, "time": "2023-06-08 17:49:45", "exception": null, "message": "Traceback (most recent call last):\n  File \"/Users/zhouzhiyong/Desktop/EasyAirflow/rest_api/utils/response_safe.py\", line 40, in wraps\n    resp = f(*args, **kwargs)\n  File \"/Users/zhouzhiyong/Desktop/EasyAirflow/rest_api/endpoints/resources/task_instance_list_resource.py\", line 85, in post\n    TaskHandlers.back_fill(task_id, dag_id, start_date, end_date)\n  File \"/Users/zhouzhiyong/Desktop/EasyAirflow/rest_api/endpoints/handlers/airflow_task_handlers.py\", line 196, in back_fill\n    dag = cls.get_dag(dag_id)\n  File \"/Users/zhouzhiyong/Desktop/EasyAirflow/rest_api/endpoints/handlers/airflow_task_handlers.py\", line 178, in get_dag\n    raise DagNotFound(\"Dag id {} not found in DagModel\".format(dag_id))\nairflow.exceptions.DagNotFound: Dag id _Landsat-task-7069854799495168000 not found in DagModel\n", "file": "response_safe.py", "line": 45, "function": "wraps", "level": "ERROR", "name": "utils.response_safe", "process": 30388, "thread": 13133619200, "extra": {}}, "trace": {"service": "airflow-plus", "hostname": "zhouzhiyongdeMac-mini.local", "span_name": null, "span_id": "0000000000000000", "trace_id": "de254e1d8738390a60e83f8e6bd9d538", "parent_span_id": null}}
{"record": {"timestamp": 1686218067642, "time": "2023-06-08 17:54:27", "exception": null, "message": "Traceback (most recent call last):\n  File \"/Users/zhouzhiyong/Desktop/EasyAirflow/rest_api/utils/response_safe.py\", line 40, in wraps\n    resp = f(*args, **kwargs)\n  File \"/Users/zhouzhiyong/Desktop/EasyAirflow/rest_api/endpoints/resources/task_instance_list_resource.py\", line 85, in post\n    TaskHandlers.back_fill(dag_id, task_id, start_date, end_date)\n  File \"/Users/zhouzhiyong/Desktop/EasyAirflow/rest_api/endpoints/handlers/airflow_task_handlers.py\", line 202, in back_fill\n    dag.run(\n  File \"/Users/zhouzhiyong/opt/anaconda3/envs/EasyAirflow/lib/python3.10/site-packages/airflow/models/dag.py\", line 2490, in run\n    run_job(job=job, execute_callable=job_runner._execute)\n  File \"/Users/zhouzhiyong/opt/anaconda3/envs/EasyAirflow/lib/python3.10/site-packages/airflow/utils/session.py\", line 76, in wrapper\n    return func(*args, session=session, **kwargs)\n  File \"/Users/zhouzhiyong/opt/anaconda3/envs/EasyAirflow/lib/python3.10/site-packages/airflow/jobs/job.py\", line 281, in run_job\n    return execute_job(job, execute_callable=execute_callable)\n  File \"/Users/zhouzhiyong/opt/anaconda3/envs/EasyAirflow/lib/python3.10/site-packages/airflow/jobs/job.py\", line 310, in execute_job\n    ret = execute_callable()\n  File \"/Users/zhouzhiyong/opt/anaconda3/envs/EasyAirflow/lib/python3.10/site-packages/airflow/utils/session.py\", line 76, in wrapper\n    return func(*args, session=session, **kwargs)\n  File \"/Users/zhouzhiyong/opt/anaconda3/envs/EasyAirflow/lib/python3.10/site-packages/airflow/jobs/backfill_job_runner.py\", line 848, in _execute\n    dagrun_start_date = timezone.coerce_datetime(start_date)\n  File \"/Users/zhouzhiyong/opt/anaconda3/envs/EasyAirflow/lib/python3.10/site-packages/airflow/utils/timezone.py\", line 246, in coerce_datetime\n    return pendulum.instance(v if v.tzinfo else make_aware(v, tz))\nAttributeError: 'str' object has no attribute 'tzinfo'\n", "file": "response_safe.py", "line": 45, "function": "wraps", "level": "ERROR", "name": "utils.response_safe", "process": 30494, "thread": 13078421504, "extra": {}}, "trace": {"service": "airflow-plus", "hostname": "zhouzhiyongdeMac-mini.local", "span_name": null, "span_id": "0000000000000000", "trace_id": "2e37109b301a06cf2fd1876ead8e710d", "parent_span_id": null}}
{"record": {"timestamp": 1686220708941, "time": "2023-06-08 18:38:28", "exception": null, "message": "Traceback (most recent call last):\n  File \"/Users/zhouzhiyong/Desktop/EasyAirflow/rest_api/utils/response_safe.py\", line 40, in wraps\n    resp = f(*args, **kwargs)\n  File \"/Users/zhouzhiyong/Desktop/EasyAirflow/rest_api/endpoints/resources/task_instance_list_resource.py\", line 87, in post\n    TaskHandlers.back_fill(dag_id, task_id, start_date, end_date)\n  File \"/Users/zhouzhiyong/Desktop/EasyAirflow/rest_api/endpoints/handlers/airflow_task_handlers.py\", line 202, in back_fill\n    dag.run(\n  File \"/Users/zhouzhiyong/opt/anaconda3/envs/EasyAirflow/lib/python3.10/site-packages/airflow/models/dag.py\", line 2490, in run\n    run_job(job=job, execute_callable=job_runner._execute)\n  File \"/Users/zhouzhiyong/opt/anaconda3/envs/EasyAirflow/lib/python3.10/site-packages/airflow/utils/session.py\", line 76, in wrapper\n    return func(*args, session=session, **kwargs)\n  File \"/Users/zhouzhiyong/opt/anaconda3/envs/EasyAirflow/lib/python3.10/site-packages/airflow/jobs/job.py\", line 281, in run_job\n    return execute_job(job, execute_callable=execute_callable)\n  File \"/Users/zhouzhiyong/opt/anaconda3/envs/EasyAirflow/lib/python3.10/site-packages/airflow/jobs/job.py\", line 310, in execute_job\n    ret = execute_callable()\n  File \"/Users/zhouzhiyong/opt/anaconda3/envs/EasyAirflow/lib/python3.10/site-packages/airflow/utils/session.py\", line 76, in wrapper\n    return func(*args, session=session, **kwargs)\n  File \"/Users/zhouzhiyong/opt/anaconda3/envs/EasyAirflow/lib/python3.10/site-packages/airflow/jobs/backfill_job_runner.py\", line 919, in _execute\n    self._execute_dagruns(\n  File \"/Users/zhouzhiyong/opt/anaconda3/envs/EasyAirflow/lib/python3.10/site-packages/airflow/utils/session.py\", line 73, in wrapper\n    return func(*args, **kwargs)\n  File \"/Users/zhouzhiyong/opt/anaconda3/envs/EasyAirflow/lib/python3.10/site-packages/airflow/jobs/backfill_job_runner.py\", line 806, in _execute_dagruns\n    processed_dag_run_dates = self._process_backfill_task_instances(\n  File \"/Users/zhouzhiyong/opt/anaconda3/envs/EasyAirflow/lib/python3.10/site-packages/airflow/jobs/backfill_job_runner.py\", line 657, in _process_backfill_task_instances\n    executor.heartbeat()\n  File \"/Users/zhouzhiyong/opt/anaconda3/envs/EasyAirflow/lib/python3.10/site-packages/airflow/executors/base_executor.py\", line 224, in heartbeat\n    self.trigger_tasks(open_slots)\n  File \"/Users/zhouzhiyong/opt/anaconda3/envs/EasyAirflow/lib/python3.10/site-packages/airflow/executors/base_executor.py\", line 282, in trigger_tasks\n    self._process_tasks(task_tuples)\n  File \"/Users/zhouzhiyong/opt/anaconda3/envs/EasyAirflow/lib/python3.10/site-packages/airflow/executors/celery_executor.py\", line 259, in _process_tasks\n    key_and_async_results = self._send_tasks_to_celery(task_tuples_to_send)\n  File \"/Users/zhouzhiyong/opt/anaconda3/envs/EasyAirflow/lib/python3.10/site-packages/airflow/executors/celery_executor.py\", line 306, in _send_tasks_to_celery\n    key_and_async_results = list(\n  File \"/Users/zhouzhiyong/opt/anaconda3/envs/EasyAirflow/lib/python3.10/concurrent/futures/process.py\", line 575, in _chain_from_iterable_of_lists\n    for element in iterable:\n  File \"/Users/zhouzhiyong/opt/anaconda3/envs/EasyAirflow/lib/python3.10/concurrent/futures/_base.py\", line 621, in result_iterator\n    yield _result_or_cancel(fs.pop())\n  File \"/Users/zhouzhiyong/opt/anaconda3/envs/EasyAirflow/lib/python3.10/concurrent/futures/_base.py\", line 319, in _result_or_cancel\n    return fut.result(timeout)\n  File \"/Users/zhouzhiyong/opt/anaconda3/envs/EasyAirflow/lib/python3.10/concurrent/futures/_base.py\", line 458, in result\n    return self.__get_result()\n  File \"/Users/zhouzhiyong/opt/anaconda3/envs/EasyAirflow/lib/python3.10/concurrent/futures/_base.py\", line 403, in __get_result\n    raise self._exception\nconcurrent.futures.process.BrokenProcessPool: A process in the process pool was terminated abruptly while the future was running or pending.\n", "file": "response_safe.py", "line": 45, "function": "wraps", "level": "ERROR", "name": "utils.response_safe", "process": 30868, "thread": 13146103808, "extra": {}}, "trace": {"service": "airflow-plus", "hostname": "zhouzhiyongdeMac-mini.local", "span_name": null, "span_id": "0000000000000000", "trace_id": "b5412dfce3eadd57ddb85cad58804335", "parent_span_id": null}}
